Workbook
Name 現場形態: [1]施工店名簿!$AC$18:$AC$19
Name 工事内容: [1]施工店名簿!$AC$6:$AC$16
Name 産廃持込: [1]施工店名簿!$AC$25:$AC$29
Name 施工店名: [1]施工店名簿!$C$6:$C$89
Name 車両制限: [1]施工店名簿!$AC$21:$AC$23
Name 品番: 商品リスト!$A$2:$A$39

Sheet 基本情報
A1: お客様基本情報
A3: お客様名：
A4: フリガナ：
A5: 住所：
A6: 電話番号：
A7: 被保険者番号：
A8: 現調依頼日：
A9: 生年月日： | B9: 昭和 | D9: 年 | F9: 月 | H9: 日

Sheet 原価
B2: 合計金額 | C2: =K19 -> 0
B3: 支払条件
B4: 有効期限
B7: 品 名 | D7: 数量 | E7: 単位 | F7: 単価 | G7: 金 額 | H7: 摘 要 | J7: 備 考
B9: =基本情報!B3 -> 0 | D9: 1 | E9: 式 | F9: =原価内訳書!H85+原価内訳書!H86 -> 0 | G9: =ROUND(D9*F9,0) -> 0
B10: 様 邸 住宅改修工事一式 | G10: =ROUND(D10*F10,0) -> 0
G11: =ROUND(D11*F11,0) -> 0
G12: =ROUND(D12*F12,0) -> 0
G13: =ROUND(D13*F13,0) -> 0
G14: =ROUND(D14*F14,0) -> 0
G15: =ROUND(D15*F15,0) -> 0
G16: =ROUND(D16*F16,0) -> 0 | J16: 小 計 | K16: =SUM(G9:G19) -> 0
G17: =ROUND(D17*F17,0) -> 0 | J17: 税率 | K17: 0.1
G18: =ROUND(D18*F18,0) -> 0 | J18: 消費税 | K18: =ROUNDDOWN(K16*K17,0) -> 0
G19: =ROUND(D19*F19,0) -> 0 | J19: 合 計 | K19: =K16+K18 -> 0

Sheet 原価内訳書
A1: ① 工 事 費 見 積 書（仕入金額）
A3: =IF(基本情報!B3="","",基本情報!B3) | D3: 様邸 住宅改修
A4: 介護保険被保険者番号 | D4: =IF(基本情報!B7="","",基本情報!B7)
A5: 工事場所（住所） | B5: =IF(基本情報!B5="","",基本情報!B5)
A7: 改修内容 （付帯工事含む） | B7: 改修場所 （写真No．） | C7: 品番 | D7: 内容（ 規格・範囲 ） | E7: 数量 | G7: 単価 | H7: 金額 | I7: 介護保険対象部分 | M7: 介護保険 対象外金額 | N7: 備考（定価等）
I8: 数量 | K8: 単価 | L8: 金額
D9: =IFERROR(VLOOKUP(C9, 商品リスト!A:B, 2, FALSE),"") | G9: =IF(C9<>"", IFERROR(VLOOKUP(C9, 商品リスト!A:C, 3, FALSE), ""), "") | H9: =IF(E9="","",E9*G9) | I9: =IF(E9="","",E9) | J9: =IF(F9="","",F9) | K9: =IF(G9="","",G9) | L9: =IF(H9="","",H9) | N9: =IFERROR(VLOOKUP(C9, 商品リスト!A:D, 4, FALSE),"") | P9: ※手すり等メートル単位の場合は単価に1メートルあたりの単価を
D10: =IFERROR(VLOOKUP(C10, 商品リスト!A:B, 2, FALSE),"") | G10: =IF(C10<>"", IFERROR(VLOOKUP(C10, 商品リスト!A:C, 3, FALSE), ""), "") | H10: =IF(E10="","",E10*G10) | I10: =IF(E10="","",E10) | J10: =IF(F10="","",F10) | K10: =IF(G10="","",G10) | L10: =IF(H10="","",H10) | N10: =IFERROR(VLOOKUP(C10, 商品リスト!A:D, 4, FALSE),"") | P10: 入力いただけると金額が表示されます。
D11: =IFERROR(VLOOKUP(C11, 商品リスト!A:B, 2, FALSE),"") | G11: =IF(C11<>"", IFERROR(VLOOKUP(C11, 商品リスト!A:C, 3, FALSE), ""), "") | H11: =IF(E11="","",E11*G11) | I11: =IF(E11="","",E11) | J11: =IF(F11="","",F11) | K11: =IF(G11="","",G11) | L11: =IF(H11="","",H11) | N11: =IFERROR(VLOOKUP(C11, 商品リスト!A:D, 4, FALSE),"") | P11: 例：1メートル単価が1000円で0.6ｍ使用する場合は1000×0.6＝600が金額として
D12: =IFERROR(VLOOKUP(C12, 商品リスト!A:B, 2, FALSE),"") | G12: =IF(C12<>"", IFERROR(VLOOKUP(C12, 商品リスト!A:C, 3, FALSE), ""), "") | H12: =IF(E12="","",E12*G12) | I12: =IF(E12="","",E12) | J12: =IF(F12="","",F12) | K12: =IF(G12="","",G12) | L12: =IF(H12="","",H12) | N12: =IFERROR(VLOOKUP(C12, 商品リスト!A:D, 4, FALSE),"") | P12: 表示されます。
D13: =IFERROR(VLOOKUP(C13, 商品リスト!A:B, 2, FALSE),"") | G13: =IF(C13<>"", IFERROR(VLOOKUP(C13, 商品リスト!A:C, 3, FALSE), ""), "") | H13: =IF(E13="","",E13*G13) | I13: =IF(E13="","",E13) | J13: =IF(F13="","",F13) | K13: =IF(G13="","",G13) | L13: =IF(H13="","",H13) | N13: =IFERROR(VLOOKUP(C13, 商品リスト!A:D, 4, FALSE),"")
D14: =IFERROR(VLOOKUP(C14, 商品リスト!A:B, 2, FALSE),"") | G14: =IF(C14<>"", IFERROR(VLOOKUP(C14, 商品リスト!A:C, 3, FALSE), ""), "") | H14: =IF(E14="","",E14*G14) | I14: =IF(E14="","",E14) | J14: =IF(F14="","",F14) | K14: =IF(G14="","",G14) | L14: =IF(H14="","",H14) | N14: =IFERROR(VLOOKUP(C14, 商品リスト!A:D, 4, FALSE),"")
D15: =IFERROR(VLOOKUP(C15, 商品リスト!A:B, 2, FALSE),"") | G15: =IF(C15<>"", IFERROR(VLOOKUP(C15, 商品リスト!A:C, 3, FALSE), ""), "") | H15: =IF(E15="","",E15*G15) | I15: =IF(E15="","",E15) | J15: =IF(F15="","",F15) | K15: =IF(G15="","",G15) | L15: =IF(H15="","",H15) | N15: =IFERROR(VLOOKUP(C15, 商品リスト!A:D, 4, FALSE),"")
D16: =IFERROR(VLOOKUP(C16, 商品リスト!A:B, 2, FALSE),"") | G16: =IF(C16<>"", IFERROR(VLOOKUP(C16, 商品リスト!A:C, 3, FALSE), ""), "") | H16: =IF(E16="","",E16*G16) | I16: =IF(E16="","",E16) | J16: =IF(F16="","",F16) | K16: =IF(G16="","",G16) | L16: =IF(H16="","",H16) | N16: =IFERROR(VLOOKUP(C16, 商品リスト!A:D, 4, FALSE),"")
D17: =IFERROR(VLOOKUP(C17, 商品リスト!A:B, 2, FALSE),"") | G17: =IF(C17<>"", IFERROR(VLOOKUP(C17, 商品リスト!A:C, 3, FALSE), ""), "") | H17: =IF(E17="","",E17*G17) | I17: =IF(E17="","",E17) | J17: =IF(F17="","",F17) | K17: =IF(G17="","",G17) | L17: =IF(H17="","",H17) | N17: =IFERROR(VLOOKUP(C17, 商品リスト!A:D, 4, FALSE),"")
D18: =IFERROR(VLOOKUP(C18, 商品リスト!A:B, 2, FALSE),"") | G18: =IF(C18<>"", IFERROR(VLOOKUP(C18, 商品リスト!A:C, 3, FALSE), ""), "") | H18: =IF(E18="","",E18*G18) | I18: =IF(E18="","",E18) | J18: =IF(F18="","",F18) | K18: =IF(G18="","",G18) | L18: =IF(H18="","",H18) | N18: =IFERROR(VLOOKUP(C18, 商品リスト!A:D, 4, FALSE),"")
D19: =IFERROR(VLOOKUP(C19, 商品リスト!A:B, 2, FALSE),"") | G19: =IF(C19<>"", IFERROR(VLOOKUP(C19, 商品リスト!A:C, 3, FALSE), ""), "") | H19: =IF(E19="","",E19*G19) | I19: =IF(E19="","",E19) | J19: =IF(F19="","",F19) | K19: =IF(G19="","",G19) | L19: =IF(H19="","",H19) | N19: =IFERROR(VLOOKUP(C19, 商品リスト!A:D, 4, FALSE),"")
D20: =IFERROR(VLOOKUP(C20, 商品リスト!A:B, 2, FALSE),"") | G20: =IF(C20<>"", IFERROR(VLOOKUP(C20, 商品リスト!A:C, 3, FALSE), ""), "") | H20: =IF(E20="","",E20*G20) | I20: =IF(E20="","",E20) | J20: =IF(F20="","",F20) | K20: =IF(G20="","",G20) | L20: =IF(H20="","",H20) | N20: =IFERROR(VLOOKUP(C20, 商品リスト!A:D, 4, FALSE),"")
D21: =IFERROR(VLOOKUP(C21, 商品リスト!A:B, 2, FALSE),"") | G21: =IF(C21<>"", IFERROR(VLOOKUP(C21, 商品リスト!A:C, 3, FALSE), ""), "") | H21: =IF(E21="","",E21*G21) | I21: =IF(E21="","",E21) | J21: =IF(F21="","",F21) | K21: =IF(G21="","",G21) | L21: =IF(H21="","",H21) | N21: =IFERROR(VLOOKUP(C21, 商品リスト!A:D, 4, FALSE),"")
D22: =IFERROR(VLOOKUP(C22, 商品リスト!A:B, 2, FALSE),"") | G22: =IF(C22<>"", IFERROR(VLOOKUP(C22, 商品リスト!A:C, 3, FALSE), ""), "") | H22: =IF(E22="","",E22*G22) | I22: =IF(E22="","",E22) | J22: =IF(F22="","",F22) | K22: =IF(G22="","",G22) | L22: =IF(H22="","",H22) | N22: =IFERROR(VLOOKUP(C22, 商品リスト!A:D, 4, FALSE),"")
D23: =IFERROR(VLOOKUP(C23, 商品リスト!A:B, 2, FALSE),"") | G23: =IF(C23<>"", IFERROR(VLOOKUP(C23, 商品リスト!A:C, 3, FALSE), ""), "") | H23: =IF(E23="","",E23*G23) | I23: =IF(E23="","",E23) | J23: =IF(F23="","",F23) | K23: =IF(G23="","",G23) | L23: =IF(H23="","",H23) | N23: =IFERROR(VLOOKUP(C23, 商品リスト!A:D, 4, FALSE),"")
D24: =IFERROR(VLOOKUP(C24, 商品リスト!A:B, 2, FALSE),"") | G24: =IF(C24<>"", IFERROR(VLOOKUP(C24, 商品リスト!A:C, 3, FALSE), ""), "") | H24: =IF(E24="","",E24*G24) | I24: =IF(E24="","",E24) | J24: =IF(F24="","",F24) | K24: =IF(G24="","",G24) | L24: =IF(H24="","",H24) | N24: =IFERROR(VLOOKUP(C24, 商品リスト!A:D, 4, FALSE),"")
... D84: =IFERROR(VLOOKUP(C84, 商品リスト!A:B, 2, FALSE),"") | G84: =IF(C84<>"", IFERROR(VLOOKUP(C84, 商品リスト!A:C, 3, FALSE), ""), "") | H84: =IF(E84="","",E84*G84) | I84: =IF(E84="","",E84) | J84: =IF(F84="","",F84) | K84: =IF(G84="","",G84) | L84: =IF(H84="","",H84) | N84: =IFERROR(VLOOKUP(C84, 商品リスト!A:D, 4, FALSE),"")
D85: 小計 | H85: =SUM(H9:H84) -> 0 | L85: =SUM(L9:L84) -> 0
D86: 諸経費 | L86: =H86 -> 0
D87: 消費税 | H87: =ROUNDDOWN((H85+H86)*(10/100),0) -> 0 | L87: =ROUNDDOWN((L85+L86)*(10/100),0) -> 0
D88: 合計 | H88: =SUM(H85:H87) -> 0 | L88: =SUM(L85:L87) -> 0

Sheet 商品リスト
A1: 品番 | B1: 商品名 【マツロク】 | C1: 仕入金額（税抜） | D1: 定価
A2: BD-122 | B2: 35φ ｱｯｼｭ丸棒ﾃﾞｨﾝﾌﾟﾙ付 040-0925 ｸﾘｱ | C2: 1630 | D2: 定価\4,400/m
A3: BD-124 | B3: 35φ ｱｯｼｭ丸棒 ﾃﾞｨﾝﾌﾟﾙ付 040-0920 ｸﾘｱ | C3: 1630 | D3: 定価\4,400/m
A4: BD-132 | B4: 35φｱｯｼｭ丸棒 ﾃﾞｨﾝﾌﾟﾙ付 040-0955 Mｵｰｸ | C4: 1630 | D4: 定価\4,400/m
A5: BD-134 | B5: 35φｱｯｼｭ丸棒 ﾃﾞｨﾝﾌﾟﾙ付 040-0950 Mｵｰｸ | C5: 1630 | D5: 定価\4,400/m
A6: BD-112 | B6: 35φ ｱｯｼｭ丸棒 ﾃﾞｨﾝﾌﾟﾙ付 040-0915 Mﾌﾞﾗｳﾝ | C6: 1630 | D6: 定価\4,400/m
A7: BD-114 | B7: 35φ ｱｯｼｭ丸棒 ﾃﾞｨﾝﾌﾟﾙ付 040-0910 Mﾌﾞﾗｳﾝ | C7: 1630 | D7: 定価\4,400/m
A8: BH-412 | B8: 木製ﾍﾞｰｽﾌﾟﾚｰﾄ15×120 040-2147 Mﾌﾞﾗｳﾝ | C8: 1685 | D8: 定価\4,550/m
A9: BH-422 | B9: 木製ﾍﾞｰｽﾌﾟﾚｰﾄ15×120 040-2157 ｸﾘｱ | C9: 1685 | D9: 定価\4,550/m
A10: BH-342 | B10: 木製ﾍﾞｰｽﾌﾟﾚｰﾄ 20X100 040-2138 Mｵｰｸ | C10: 1685 | D10: 定価\4,550/m
A11: BH-414 | B11: 木製ﾍﾞｰｽﾌﾟﾚｰﾄ15×120 040-2142 Mﾌﾞﾗｳﾝ | C11: 1665 | D11: 定価\4,550/m
A12: BH-444 | B12: 木製ﾍﾞｰｽﾌﾟﾚｰﾄ15×120 040-2163 Mｵｰｸ | C12: 1665 | D12: 定価\4,550/m
A13: BH-424 | B13: 木製ﾍﾞｰｽﾌﾟﾚｰﾄ15×120 040-2152 クリア | C13: 1665 | D13: 定価\4,550/m
... A30: BD-14G | B30: 35φ 出隅ﾌﾞﾗｹｯﾄｶﾊﾞ-付き 040-1081 ｺﾞｰﾙﾄﾞ | C30: 690 | D30: 定価\1,850
A31: BD-14S | B31: 35φ 出隅ﾌﾞﾗｹｯﾄｶﾊﾞ-付き 040-1082 ｼﾙﾊﾞｰ | C31: 690 | D31: 定価\1,850 | G31: 115270
A32: BD-45B | B32: 35φ 出隅ｽﾘﾑ座ﾌﾞﾗｹｯﾄｶﾊﾞｰﾂｷ 040-1137 ﾌﾞﾗｳﾝ | C32: 740 | D32: 定価\2,000
A33: BD-45G | B33: 35φ 出隅ｽﾘﾑ座ﾌﾞﾗｹｯﾄｶﾊﾞｰﾂｷ 040-1138 ｺﾞｰﾙﾄﾞ | C33: 740 | D33: 定価\2,000
A34: BD-45S | B34: 35φ 出隅ｽﾘﾑ座ﾌﾞﾗｹｯﾄｶﾊﾞｰﾂｷ 040-1139 | C34: 740 | D34: 定価\2,000
A35: BD-10LG | B35: 35φ 横受ｴﾝﾄﾞﾌﾞﾗｹｯﾄ 左用 040-1061 | C35: 710 | D35: 定価\1,900
A36: BD-10RG | B36: 35φ 横受ｴﾝﾄﾞﾌﾞﾗｹｯﾄ 右用 040-1056 | C36: 710 | D36: 定価\1,900
A37: BD-05G | B37: 35φﾌﾞﾗｹｯﾄ縦型ｶﾊﾞｰ付 040-1031 ｺﾞｰﾙﾄﾞ | C37: 500 | D37: 定価\1,350
A38: BD-05B | B38: 35φﾌﾞﾗｹｯﾄ縦型ｶﾊﾞｰ付 040-1030 ﾌﾞﾗｳﾝ | C38: 500 | D38: 定価\1,350
A39: BD-05S | B39: 35φﾌﾞﾗｹｯﾄ縦型ｶﾊﾞｰ付 040-1032 ｼﾙﾊﾞｰ | C39: 500 | D39: 定価\1,350
A40: BJ-22WD | B40: ﾌﾘ-Rﾚ-ﾙ 直棒手すり/木目ﾀﾞｰｸ/ 040-2722 | C40: 3079 | D40: 定価\6,550/m
A41: BJ-21WD | B41: ﾌﾘ-Rﾚ-ﾙ直棒手すり/木目ﾀﾞｰｸ/040-2721 | C41: 2832 | D41: 定価\6,025/m
A42: BJ-20WN | B42: ﾌﾘｰRﾚｰﾙ 直棒手すり/木目ﾅﾁｭﾗﾙ/040-2720 | C42: 3079 | D42: 定価\6,550/m
A43: BJ-19WN | B43: ﾌﾘ-Rﾚ-ﾙ直棒手すり/木目ﾅﾁｭﾗﾙ/040-2719 | C43: 2832 | D43: 定価\6,025/m
... A220: BJ-236DB | B220: ｵﾌｾｯﾄﾌﾞﾗｹｯﾄ 040-3142 ﾀﾞｰｸﾌﾞﾛﾝｽﾞ | C220: 7990 | D220: 定価\17,000
A223: 品番 | B223: 商品名 【インテリアバー】 | C223: 仕入金額（税抜） | D223: 定価
A224: TS136GY3 | B224: ｲﾝﾃﾘｱ・ﾊﾞｰ Ｆｼﾘｰｽﾞ Ｉﾀｲﾌﾟ（ｿﾌﾄﾒｯｼｭ）/#NW1ﾎﾜｲﾄ/L300 | C224: 3097 | D224: 定価\9,100
A225: TS136GY4R | B225: ｲﾝﾃﾘｱ・ﾊﾞｰ Ｆｼﾘｰｽﾞ Ｉﾀｲﾌﾟ（ｿﾌﾄﾒｯｼｭ）/#NW1ﾎﾜｲﾄ/L400 | C225: 3247 | D225: 定価\9,550
A226: TS136GY5 | B226: ｲﾝﾃﾘｱ・ﾊﾞｰ Ｆｼﾘｰｽﾞ Ｉﾀｲﾌﾟ（ｿﾌﾄﾒｯｼｭ）/#NW1ﾎﾜｲﾄ/L500 | C226: 3400 | D226: 定価\10,000
A227: TS136GY6R | B227: ｲﾝﾃﾘｱ・ﾊﾞｰ Fｼﾘｰｽﾞ Ｉﾀｲﾌﾟ（ｿﾌﾄﾒｯｼｭ）/#NW1ﾎﾜｲﾄ/L600 | C227: 3570 | D227: 定価\10,500
A228: TS136GY7 | B228: ｲﾝﾃﾘｱ・ﾊﾞｰ Fｼﾘｰｽﾞ Ｉﾀｲﾌﾟ（ｿﾌﾄﾒｯｼｭ）/#NW1ﾎﾜｲﾄ/L700 | C228: 3706 | D228: 定価\10,900
A229: TS136GY8R | B229: ｲﾝﾃﾘｱ・ﾊﾞｰ Ｆｼﾘｰｽﾞ Ｉﾀｲﾌﾟ（ｿﾌﾄﾒｯｼｭ）/#NW1ﾎﾜｲﾄ/L800 | C229: 3876 | D229: 定価\11,400
A230: TS136GY9 | B230: ｲﾝﾃﾘｱ・ﾊﾞｰ Ｆｼﾘｰｽﾞ Ｉﾀｲﾌﾟ（ｿﾌﾄﾒｯｼｭ）/#NW1ﾎﾜｲﾄ/L900 | C230: 4012 | D230: 定価\11,800
A231: TS136GY12 | B231: ｲﾝﾃﾘｱ・ﾊﾞｰ Ｆｼﾘｰｽﾞ Ｉﾀｲﾌﾟ（ｿﾌﾄﾒｯｼｭ）/#NW1ﾎﾜｲﾄ/L1200 | C231: 5984 | D231: 定価\17,600
A232: TS136GLY64 | B232: ｲﾝﾃﾘｱ･ﾊﾞｰFｼﾘｰｽﾞ(Lﾀｲﾌﾟｿﾌﾄﾒｯｼｭ)/#NW1ﾎﾜｲﾄ/L600×400 | C232: 5984 | D232: 定価\17,600
A233: TS136GLY66 | B233: ｲﾝﾃﾘｱ･ﾊﾞｰFｼﾘｰｽﾞ(Lﾀｲﾌﾟｿﾌﾄﾒｯｼｭ)/#NW1ﾎﾜｲﾄ/L600×600 | C233: 6358 | D233: 定価\18,700
A234: TS136GLY86 | B234: ｲﾝﾃﾘｱ･ﾊﾞｰFｼﾘｰｽﾞ(Lﾀｲﾌﾟｿﾌﾄﾒｯｼｭ)/#NW1ﾎﾜｲﾄ/L600×800 | C234: 6732 | D234: 定価\19,800
...

Sheet お客様提示用見積書表紙
K1: 2026年7月 日
O2: ※日付は入力して下さい。
A3: 御 見 積 書
A7: =基本情報!B3 -> 0 | E7: 様邸 | O7: ※宛名は基本情報に準じてます。変更がある場合は上書き。
A11: 下記の通りお見積りを申し上げます。 何卒ご用命賜ります様よろしくお願い申し上げます。
A14: お見積金額（税込） | D14: =お客様提示用内訳書!H50 -> 0 | G14: 円 | O14: ※見積書金額は内訳合計です。
A19: 工事名 | D19: =基本情報!B3 -> 0 | G19: 様邸 改修工事 | O19: ※基本情報氏名+「様邸 改修工事」。変更がある場合は上書き。
A21: 工事場所 | D21: =基本情報!B5 -> 0 | O21: ※基本情報の住所。変更がある場合は上書き。
A23: 工期
A25: 見積もり有効期限
O26: ※見積もり有効期限は手入力
A27: お支払い条件
O28: ※お支払い条件は手入力
I32: 住 所 福岡市西区小戸1丁目16-24 施工業者名 ㈱介福本舗 代表者名 眞田 友寿 担当者・電話番号 担当： 092-985-0904 | P32: 住 所 福岡市博多区東那珂2-11-30 施工業者名 ㈱介福本舗 博多営業所 代表者名 眞田 友寿 担当者・電話番号 担当・山下 遼 092-482-3030
A33: 責任者 | B33: 担当者
P40: 住 所 筑後市和泉210-1 施工業者名 ㈱介福本舗 筑後営業所 代表者名 眞田 友寿 担当者・電話番号 担当：喜田 慎太郎 0942-42-1117

Sheet お客様提示用内訳書
A1: ① 工 事 費 見 積 書 | M1: 2026/7/ | O1: ←入力 | P1: この枠内は印刷されません。
I2: 住 所 福岡市西区小戸1丁目16-24 施工業者名 ㈱介福本舗 代表者名 眞田 友寿 担当者・電話番号 担当： 092-985-0904 | Q2: ↓粗利率を入力 | U2: 住 所 福岡市博多区東那珂2-11-30 施工業者名 ㈱介福本舗 博多営業所 代表者名 眞田 友寿 担当者・電話番号 担当：山下 遼 092-482-3030
A3: =IF(基本情報!B3="","",基本情報!B3) | D3: 様邸 住宅改修 | P3: 粗利率は | Q3: 50 | R3: ％で計算
A4: 介護保険被保険者番号 | D4: =IF(基本情報!B7="","",基本情報!B7)
A5: 工事場所（住所） | B5: =IF(基本情報!B5="","",基本情報!B5)
A7: 改修内容 （付帯工事含む） | B7: 改修場所 （写真No．） | C7: 品番 | D7: 内容（ 規格・範囲 ） | E7: 数量 | G7: 単価 | H7: 金額 | I7: 介護保険対象部分 | M7: 介護保険 対象外金額 | N7: 備考（定価等） | O7: 粗利率 （手入力した 場合の 参考値） | R7: ※介護保険対象外がある場合は計算式を崩して使用。
I8: 数量 | K8: 単価 | L8: 金額
A9: =IF(原価内訳書!A9="","",原価内訳書!A9) | B9: =IF(原価内訳書!B9="","",原価内訳書!B9) | C9: =IF(原価内訳書!C9="","",原価内訳書!C9) | D9: =IF(原価内訳書!D9="","",原価内訳書!D9) | E9: =IF(原価内訳書!E9="","",原価内訳書!E9) | F9: =IF(原価内訳書!F9="","",原価内訳書!F9) | G9: =IF(原価内訳書!G9="","",原価内訳書!G9/(1-お客様提示用内訳書!$Q$3/100)) | H9: =IF(G9="","",E9*G9) | I9: =IF(E9="","",E9) | J9: =IF(F9="","",F9) | K9: =IF(G9="","",G9) | L9: =IF(H9="","",H9) | N9: =IF(原価内訳書!N9="","",原価内訳書!N9) | O9: =IF(H9="","",1-(原価内訳書!H9/お客様提示用内訳書!H9))
A10: =IF(原価内訳書!A10="","",原価内訳書!A10) | B10: =IF(原価内訳書!B10="","",原価内訳書!B10) | C10: =IF(原価内訳書!C10="","",原価内訳書!C10) | D10: =IF(原価内訳書!D10="","",原価内訳書!D10) | E10: =IF(原価内訳書!E10="","",原価内訳書!E10) | F10: =IF(原価内訳書!F10="","",原価内訳書!F10) | G10: =IF(原価内訳書!G10="","",原価内訳書!G10/(1-お客様提示用内訳書!$Q$3/100)) | H10: =IF(G10="","",E10*G10) | I10: =IF(E10="","",E10) | J10: =IF(F10="","",F10) | K10: =IF(G10="","",G10) | L10: =IF(H10="","",H10) | N10: =IF(原価内訳書!N10="","",原価内訳書!N10) | O10: =IF(H10="","",1-(原価内訳書!H10/お客様提示用内訳書!H10)) | U10: 住 所 筑後市和泉210-1 施工業者名 ㈱介福本舗 筑後営業所 代表者名 眞田 友寿 担当者・電話番号 担当： 喜田 慎太郎 0942-42-1117
A11: =IF(原価内訳書!A11="","",原価内訳書!A11) | B11: =IF(原価内訳書!B11="","",原価内訳書!B11) | C11: =IF(原価内訳書!C11="","",原価内訳書!C11) | D11: =IF(原価内訳書!D11="","",原価内訳書!D11) | E11: =IF(原価内訳書!E11="","",原価内訳書!E11) | F11: =IF(原価内訳書!F11="","",原価内訳書!F11) | G11: =IF(原価内訳書!G11="","",原価内訳書!G11/(1-お客様提示用内訳書!$Q$3/100)) | H11: =IF(G11="","",E11*G11) | I11: =IF(E11="","",E11) | J11: =IF(F11="","",F11) | K11: =IF(G11="","",G11) | L11: =IF(H11="","",H11) | N11: =IF(原価内訳書!N11="","",原価内訳書!N11) | O11: =IF(H11="","",1-(原価内訳書!H11/お客様提示用内訳書!H11))
A12: =IF(原価内訳書!A12="","",原価内訳書!A12) | B12: =IF(原価内訳書!B12="","",原価内訳書!B12) | C12: =IF(原価内訳書!C12="","",原価内訳書!C12) | D12: =IF(原価内訳書!D12="","",原価内訳書!D12) | E12: =IF(原価内訳書!E12="","",原価内訳書!E12) | F12: =IF(原価内訳書!F12="","",原価内訳書!F12) | G12: =IF(原価内訳書!G12="","",原価内訳書!G12/(1-お客様提示用内訳書!$Q$3/100)) | H12: =IF(G12="","",E12*G12) | I12: =IF(E12="","",E12) | J12: =IF(F12="","",F12) | K12: =IF(G12="","",G12) | L12: =IF(H12="","",H12) | N12: =IF(原価内訳書!N12="","",原価内訳書!N12) | O12: =IF(H12="","",1-(原価内訳書!H12/お客様提示用内訳書!H12))
A13: =IF(原価内訳書!A13="","",原価内訳書!A13) | B13: =IF(原価内訳書!B13="","",原価内訳書!B13) | C13: =IF(原価内訳書!C13="","",原価内訳書!C13) | D13: =IF(原価内訳書!D13="","",原価内訳書!D13) | E13: =IF(原価内訳書!E13="","",原価内訳書!E13) | F13: =IF(原価内訳書!F13="","",原価内訳書!F13) | G13: =IF(原価内訳書!G13="","",原価内訳書!G13/(1-お客様提示用内訳書!$Q$3/100)) | H13: =IF(G13="","",E13*G13) | I13: =IF(E13="","",E13) | J13: =IF(F13="","",F13) | K13: =IF(G13="","",G13) | L13: =IF(H13="","",H13) | N13: =IF(原価内訳書!N13="","",原価内訳書!N13) | O13: =IF(H13="","",1-(原価内訳書!H13/お客様提示用内訳書!H13))
A14: =IF(原価内訳書!A14="","",原価内訳書!A14) | B14: =IF(原価内訳書!B14="","",原価内訳書!B14) | C14: =IF(原価内訳書!C14="","",原価内訳書!C14) | D14: =IF(原価内訳書!D14="","",原価内訳書!D14) | E14: =IF(原価内訳書!E14="","",原価内訳書!E14) | F14: =IF(原価内訳書!F14="","",原価内訳書!F14) | G14: =IF(原価内訳書!G14="","",原価内訳書!G14/(1-お客様提示用内訳書!$Q$3/100)) | H14: =IF(G14="","",E14*G14) | I14: =IF(E14="","",E14) | J14: =IF(F14="","",F14) | K14: =IF(G14="","",G14) | L14: =IF(H14="","",H14) | N14: =IF(原価内訳書!N14="","",原価内訳書!N14) | O14: =IF(H14="","",1-(原価内訳書!H14/お客様提示用内訳書!H14))
A15: =IF(原価内訳書!A15="","",原価内訳書!A15) | B15: =IF(原価内訳書!B15="","",原価内訳書!B15) | C15: =IF(原価内訳書!C15="","",原価内訳書!C15) | D15: =IF(原価内訳書!D15="","",原価内訳書!D15) | E15: =IF(原価内訳書!E15="","",原価内訳書!E15) | F15: =IF(原価内訳書!F15="","",原価内訳書!F15) | G15: =IF(原価内訳書!G15="","",原価内訳書!G15/(1-お客様提示用内訳書!$Q$3/100)) | H15: =IF(G15="","",E15*G15) | I15: =IF(E15="","",E15) | J15: =IF(F15="","",F15) | K15: =IF(G15="","",G15) | L15: =IF(H15="","",H15) | N15: =IF(原価内訳書!N15="","",原価内訳書!N15) | O15: =IF(H15="","",1-(原価内訳書!H15/お客様提示用内訳書!H15))
A16: =IF(原価内訳書!A16="","",原価内訳書!A16) | B16: =IF(原価内訳書!B16="","",原価内訳書!B16) | C16: =IF(原価内訳書!C16="","",原価内訳書!C16) | D16: =IF(原価内訳書!D16="","",原価内訳書!D16) | E16: =IF(原価内訳書!E16="","",原価内訳書!E16) | F16: =IF(原価内訳書!F16="","",原価内訳書!F16) | G16: =IF(原価内訳書!G16="","",原価内訳書!G16/(1-お客様提示用内訳書!$Q$3/100)) | H16: =IF(G16="","",E16*G16) | I16: =IF(E16="","",E16) | J16: =IF(F16="","",F16) | K16: =IF(G16="","",G16) | L16: =IF(H16="","",H16) | N16: =IF(原価内訳書!N16="","",原価内訳書!N16) | O16: =IF(H16="","",1-(原価内訳書!H16/お客様提示用内訳書!H16))
A17: =IF(原価内訳書!A17="","",原価内訳書!A17) | B17: =IF(原価内訳書!B17="","",原価内訳書!B17) | C17: =IF(原価内訳書!C17="","",原価内訳書!C17) | D17: =IF(原価内訳書!D17="","",原価内訳書!D17) | E17: =IF(原価内訳書!E17="","",原価内訳書!E17) | F17: =IF(原価内訳書!F17="","",原価内訳書!F17) | G17: =IF(原価内訳書!G17="","",原価内訳書!G17/(1-お客様提示用内訳書!$Q$3/100)) | H17: =IF(G17="","",E17*G17) | I17: =IF(E17="","",E17) | J17: =IF(F17="","",F17) | K17: =IF(G17="","",G17) | L17: =IF(H17="","",H17) | N17: =IF(原価内訳書!N17="","",原価内訳書!N17) | O17: =IF(H17="","",1-(原価内訳書!H17/お客様提示用内訳書!H17))
A18: =IF(原価内訳書!A18="","",原価内訳書!A18) | B18: =IF(原価内訳書!B18="","",原価内訳書!B18) | C18: =IF(原価内訳書!C18="","",原価内訳書!C18) | D18: =IF(原価内訳書!D18="","",原価内訳書!D18) | E18: =IF(原価内訳書!E18="","",原価内訳書!E18) | F18: =IF(原価内訳書!F18="","",原価内訳書!F18) | G18: =IF(原価内訳書!G18="","",原価内訳書!G18/(1-お客様提示用内訳書!$Q$3/100)) | H18: =IF(G18="","",E18*G18) | I18: =IF(E18="","",E18) | J18: =IF(F18="","",F18) | K18: =IF(G18="","",G18) | L18: =IF(H18="","",H18) | N18: =IF(原価内訳書!N18="","",原価内訳書!N18) | O18: =IF(H18="","",1-(原価内訳書!H18/お客様提示用内訳書!H18))
A19: =IF(原価内訳書!A19="","",原価内訳書!A19) | B19: =IF(原価内訳書!B19="","",原価内訳書!B19) | C19: =IF(原価内訳書!C19="","",原価内訳書!C19) | D19: =IF(原価内訳書!D19="","",原価内訳書!D19) | E19: =IF(原価内訳書!E19="","",原価内訳書!E19) | F19: =IF(原価内訳書!F19="","",原価内訳書!F19) | G19: =IF(原価内訳書!G19="","",原価内訳書!G19/(1-お客様提示用内訳書!$Q$3/100)) | H19: =IF(G19="","",E19*G19) | I19: =IF(E19="","",E19) | J19: =IF(F19="","",F19) | K19: =IF(G19="","",G19) | L19: =IF(H19="","",H19) | N19: =IF(原価内訳書!N19="","",原価内訳書!N19) | O19: =IF(H19="","",1-(原価内訳書!H19/お客様提示用内訳書!H19))
A20: =IF(原価内訳書!A20="","",原価内訳書!A20) | B20: =IF(原価内訳書!B20="","",原価内訳書!B20) | C20: =IF(原価内訳書!C20="","",原価内訳書!C20) | D20: =IF(原価内訳書!D20="","",原価内訳書!D20) | E20: =IF(原価内訳書!E20="","",原価内訳書!E20) | F20: =IF(原価内訳書!F20="","",原価内訳書!F20) | G20: =IF(原価内訳書!G20="","",原価内訳書!G20/(1-お客様提示用内訳書!$Q$3/100)) | H20: =IF(G20="","",E20*G20) | I20: =IF(E20="","",E20) | J20: =IF(F20="","",F20) | K20: =IF(G20="","",G20) | L20: =IF(H20="","",H20) | N20: =IF(原価内訳書!N20="","",原価内訳書!N20) | O20: =IF(H20="","",1-(原価内訳書!H20/お客様提示用内訳書!H20))
A21: =IF(原価内訳書!A21="","",原価内訳書!A21) | B21: =IF(原価内訳書!B21="","",原価内訳書!B21) | C21: =IF(原価内訳書!C21="","",原価内訳書!C21) | D21: =IF(原価内訳書!D21="","",原価内訳書!D21) | E21: =IF(原価内訳書!E21="","",原価内訳書!E21) | F21: =IF(原価内訳書!F21="","",原価内訳書!F21) | G21: =IF(原価内訳書!G21="","",原価内訳書!G21/(1-お客様提示用内訳書!$Q$3/100)) | H21: =IF(G21="","",E21*G21) | I21: =IF(E21="","",E21) | J21: =IF(F21="","",F21) | K21: =IF(G21="","",G21) | L21: =IF(H21="","",H21) | N21: =IF(原価内訳書!N21="","",原価内訳書!N21) | O21: =IF(H21="","",1-(原価内訳書!H21/お客様提示用内訳書!H21))
A22: =IF(原価内訳書!A22="","",原価内訳書!A22) | B22: =IF(原価内訳書!B22="","",原価内訳書!B22) | C22: =IF(原価内訳書!C22="","",原価内訳書!C22) | D22: =IF(原価内訳書!D22="","",原価内訳書!D22) | E22: =IF(原価内訳書!E22="","",原価内訳書!E22) | F22: =IF(原価内訳書!F22="","",原価内訳書!F22) | G22: =IF(原価内訳書!G22="","",原価内訳書!G22/(1-お客様提示用内訳書!$Q$3/100)) | H22: =IF(G22="","",E22*G22) | I22: =IF(E22="","",E22) | J22: =IF(F22="","",F22) | K22: =IF(G22="","",G22) | L22: =IF(H22="","",H22) | N22: =IF(原価内訳書!N22="","",原価内訳書!N22) | O22: =IF(H22="","",1-(原価内訳書!H22/お客様提示用内訳書!H22))
... A46: =IF(原価内訳書!A46="","",原価内訳書!A46) | B46: =IF(原価内訳書!B46="","",原価内訳書!B46) | C46: =IF(原価内訳書!C46="","",原価内訳書!C46) | D46: =IF(原価内訳書!D46="","",原価内訳書!D46) | E46: =IF(原価内訳書!E46="","",原価内訳書!E46) | F46: =IF(原価内訳書!F46="","",原価内訳書!F46) | G46: =IF(原価内訳書!G46="","",原価内訳書!G46/(1-お客様提示用内訳書!$Q$3/100)) | H46: =IF(G46="","",E46*G46) | I46: =IF(E46="","",E46) | J46: =IF(F46="","",F46) | K46: =IF(G46="","",G46) | L46: =IF(H46="","",H46) | N46: =IF(原価内訳書!N46="","",原価内訳書!N46) | O46: =IF(H46="","",1-(原価内訳書!H46/お客様提示用内訳書!H46))
D47: 小計 | H47: =SUM(H9:H46) -> 0 | L47: =SUM(L9:L46) -> 0 | O47: =IF(H47="","",1-(原価内訳書!H85/お客様提示用内訳書!H47)) -> #DIV/0!
D48: 諸経費 | L48: =IF(H48="","",H48) | O48: =IF(H48="","",1-(原価内訳書!H86/お客様提示用内訳書!H48))
D49: 消費税 | H49: =ROUNDDOWN((H47+H48)*(10/100),0) -> 0 | L49: =ROUNDDOWN((L47+L48)*(10/100),0) -> #VALUE! | M49: =ROUNDDOWN(M47*(8/100),0) -> 0 | O49: =IF(H49="","",1-(原価内訳書!H87/お客様提示用内訳書!H49)) -> #DIV/0!
D50: 合計 | H50: =SUM(H47:H49) -> 0 | L50: =SUM(L47:L49) -> #VALUE! | M50: =SUM(M47:M49) -> 0 | O50: =IF(H50="","",1-(原価内訳書!H88/お客様提示用内訳書!H50)) -> #DIV/0! | P50: ←ここが最終利益率！！

Sheet 写真貼付台紙
A1: 住宅改修に伴う工事写真
A3: 被保険者名 | C3: =基本情報!B3 -> 0 | E3: 様 | F3: 被保険者番号 | H3: =基本情報!B7 -> 0
A4: 改修の場所 | C4: 屋外 | F4: 写真番号 | H4: ①
A6: 改修の内容 | C6: 手すりの取付
A8: メ モ | C8: 改修前のイメージ図
A31: メ モ | C31: 改修後の写真
B54: ※完了後に確認出来ない部分は、施工中の写真を撮影し裏面に貼附してください。
A55: 住宅改修に伴う工事写真
A57: 被保険者名 | C57: =基本情報!B3 -> 0 | E57: 様 | F57: 被保険者番号 | H57: =基本情報!B7 -> 0
A58: 改修の場所 | C58: 浴室 | F58: 写真番号 | H58: ②
A60: 改修の内容 | C60: 手すりの取付
A62: メ モ | C62: 改修前のイメージ図
A85: メ モ | C85: 改修後の写真
B108: ※完了後に確認出来ない部分は、施工中の写真を撮影し裏面に貼附してください。
A109: 住宅改修に伴う工事写真
A111: 被保険者名 | C111: =基本情報!B3 -> 0 | E111: 様 | F111: 被保険者番号 | H111: =基本情報!B7 -> 0
A112: 改修の場所 | C112: 浴室 | F112: 写真番号 | H112: ③
A114: 改修の内容 | C114: 手すりの取付け
A116: メ モ | C116: 改修前のイメージ図
A139: メ モ | C139: 改修後の写真
B162: ※完了後に確認出来ない部分は、施工中の写真を撮影し裏面に貼附してください。
A163: 住宅改修に伴う工事写真
A165: 被保険者名 | C165: =基本情報!B3 -> 0 | E165: 様 | F165: 被保険者番号 | H165: =基本情報!B7 -> 0
A166: 改修の場所 | C166: 玄関ポーチ | F166: 写真番号 | H166: ④
A168: 改修の内容 | C168: 手すりの取付
A170: メ モ | C170: 改修前のイメージ図
A193: メ モ | C193: 改修後の写真
B216: ※完了後に確認出来ない部分は、施工中の写真を撮影し裏面に貼附してください。
A217: 住宅改修に伴う工事写真
A219: 被保険者名 | C219: =基本情報!B3 -> 0 | E219: 様 | F219: 被保険者番号 | H219: =基本情報!B7 -> 0
A220: 改修の場所 | C220: 屋外階段 | F220: 写真番号 | H220: ⑤
A222: 改修の内容 | C222: 手すりの取付
A224: メ モ | C224: 改修前のイメージ図
A247: メ モ | C247: 改修後の写真
B270: ※完了後に確認出来ない部分は、施工中の写真を撮影し裏面に貼附してください。
A271: 住宅改修に伴う工事写真
A273: 被保険者名 | C273: =基本情報!B3 -> 0 | E273: 様 | F273: 被保険者番号 | H273: =基本情報!B7 -> 0
A274: 改修の場所 | C274: トイレ | F274: 写真番号 | H274: ⑥
A276: 改修の内容 | C276: 手すりの取付
A278: メ モ | C278: 改修前のイメージ図
...

Sheet 申請用図面
M35: 設計№1 | R35: 縮尺 1/ | W35: 作成 | Z35: =NOW() -> 46209.478 | AH35: ㈱介福本舗
A36: =基本情報!B3 -> 0 | J36: 様邸 | W36: 訂正 年 月 日
M37: 図面№1 | W37: 訂正 年 月 日
W38: 訂正 年 月 日

Sheet 支給申請書
C2: 様式第21号 | P2: 受付番号
C4: 介護保険住宅改修費支給申請書
C6: 被保険者 | D6: フリガナ | E6: =基本情報!B4 -> 0 | N6: 保険者番号 | T6: 4 | U6: 0 | V6: 1 | W6: 3
D7: 氏名 | E7: =基本情報!B3 -> 0
N8: 被保険者証 番号 | P8: =MID(基本情報!B7,1,1) | Q8: =MID(基本情報!B7,2,1) | R8: =MID(基本情報!B7,3,1) | S8: =MID(基本情報!B7,4,1) | T8: =MID(基本情報!B7,5,1) | U8: =MID(基本情報!B7,6,1) | V8: =MID(基本情報!B7,7,1) | W8: =MID(基本情報!B7,8,1) | X8: =MID(基本情報!B7,9,1) | Y8: =MID(基本情報!B7,10,1)
D9: 生年月日 | E9: 明・大・昭 | H9: =基本情報!C9 -> 0 | I9: 年 | J9: =基本情報!E9 -> 0 | K9: 月 | L9: =基本情報!G9 -> 0 | M9: 日
C10: 改修の内容 | G10: 改 修 箇 所 （規模・数量等）
C11: 手すりの取付け
C12: 段差の解消
C13: 床又は通路面の材料変更
C14: 引き戸等への扉の取替え | AA14: ※太枠欄のみ記入してください。
C15: 洋式便器等への取替え
C16: 住宅の所有者 | O16: 本人との続柄 （ | X16: ）
C17: 被保険者の状況 | G17: 在宅 ・ 入院（入所)中 | N17: 着工予定日 | Q17: 年 月 日頃
C18: 改修予定費用 | G18: 円 | M18: 既に支給済の 10/9,10/8又は10/7の額 | Q18: 円
C19: 改修施工者 | G19: （株）介福本舗
C20: 住宅改修費の受領委任払 | G20: １．利用する ２．利用しない | M20: 住宅改造助成事業 | Q20: １．利用する ２．利用しない
C22: 上記のとおり住宅改修を行いたいので，関係書類を添えて申請します。
C23: 令和 年 月 日
C24: （あて先）
D25: 福岡市 | F25: 区長 | H25: 申請者 | J25: 住 所 | L25: =基本情報!B5 -> 0
J26: 氏 名
L27: 日中の連絡先 | O27: （電話 － ） | P27: =基本情報!B6 -> 0
B34: 保 険 者 処 理 欄
B35: □所有者承諾書 □理由書（資格証明付） □見積書等 | N35: 改修を行う住宅 | S35: 受付印
B36: □改修前の写真 □図面 | N36: □証記載住所 □それ以外
B37: 保険料納付状況 | G37: 給 付 制 限
B38: 滞 納 □無 □有 | G38: □無 □有（償還払・差止・給付率）・期間（ ～ ）
B39: 既支給実績 | J39: 資格・介護認定 | P39: 受付者
B40: 現住居 □無 □有（既支給額 ） | J40: □資格・認定（ → ）

Sheet 完了届出書（受領委任用)
C2: 様式第22号の２ | P2: 受付番号
C4: 介護保険住宅改修完了届出書【受領委任払用】
C6: 被保険者 | D6: フリガナ | E6: =基本情報!B4 -> 0 | N6: 保険者番号 | T6: 4 | U6: 0 | V6: 1 | W6: 3
D7: 氏名 | E7: =基本情報!B3 -> 0
N8: 被保険者番号 | P8: =MID(基本情報!B7,1,1) | Q8: =MID(基本情報!B7,2,1) | R8: =MID(基本情報!B7,3,1) | S8: =MID(基本情報!B7,4,1) | T8: =MID(基本情報!B7,5,1) | U8: =MID(基本情報!B7,6,1) | V8: =MID(基本情報!B7,7,1) | W8: =MID(基本情報!B7,8,1) | X8: =MID(基本情報!B7,9,1) | Y8: =MID(基本情報!B7,10,1)
D9: 生年月日 | E9: 明・大・昭 | H9: =基本情報!C9 -> 0 | I9: 年 | J9: =基本情報!E9 -> 0 | K9: 月 | L9: =基本情報!G9 -> 0 | M9: 日
C10: 改修の内容 | G10: 改 修 箇 所 （規模・数量等）
C11: 手すりの取付け
C12: 段差の解消
C13: 床又は通路面の材料変更 | AA13: ※着工前に住宅改修費支給申請書の提出が必要です。 | AB13: ※振込先口座は、受任者名義の口座を記入して下さい。
C14: 引き戸等への扉の取替え
C15: 洋式便器等への取替え
C16: 改修施工者 | F16: （株）介福本舗 | M16: 着 工 日 | U16: 年 | W16: 月 | Y16: 日
C17: 改修費用 | L17: 円 | M17: 完 成 日 | U17: 年 | W17: 月 | Y17: 日
C18: 事前申請からの工事内容変更なしのため、工事内訳書、図面の添付を省略 （該当する場合は、□にüをしてください。） | V18: □
D19: 上記のとおり住宅改修が完了しましたので、関係書類を添えて届出します。
C20: 令和 年 月 日
C21: （あて先）
D22: 福岡市 | F22: 区長 | H22: 申請者 | J22: 住 所 | L22: =基本情報!B5 -> 0
H23: （委任者） | J23: 氏 名
L24: 日中の連絡先 | O24: （電話 ）
D26: なお、上記届出に基づく、住宅改修費の受領は、下記の者に委任します。
C27: 改修施工者（受任者） | D27: 住所 | E27: 〒819-0001
E28: 福岡市西区小戸1－16－24 | O28: （電話 092-985-0904 ）
D29: 名称 | E29: （株）介福本舗 | M29: 代表者氏名 | P29: 代表取締役 眞田友寿
D31: 振込先 金融機関 | E31: 西日本シティ | M31: 銀行 | N31: 下山門 | Y31: 本店
M32: 農協 | Y32: 支店
D33: 口座番号 | E33: 普通 当座 | G33: 655769 | M33: （フリガナ） | P33: （ | Q33: （ｶ）ｶｲﾌｸﾎﾝﾎﾟ ﾀﾞｲﾞﾋｮｳﾄﾘｼﾏﾘﾔｸ ﾏﾅﾀﾞﾄﾓﾋｻ | Y33: ）
M34: 口座名義人 | P34: （株）介福本舗 代表取締役 眞田友寿
B36: 給付制限 | G36: 保険料納付状況 | K36: 今回改修総費用査定額（20万円を限度） | Q36: Ａ | Y36: 円
B37: □無 □有（償還払・差止・給付率） | G37: 滞納 □無 □有 | K37: 既に支給した住宅改修費の額 （ 円）の（ ）分の１００の額 | Q37: Ｂ | Y37: 円
B38: 受付年月日 | G38: 改修を行う住宅 | K38: 支給限度基準額の残額（２０万円－Ｂ） | Q38: Ｃ | Y38: 円
G39: □証記載住所 □それ以外 | K39: 保険給付対象額 | N39: ＡまたはＣの いずれか低い額 | Q39: D | Y39: 円
G40: 資格・介護認定 | K40: 支給額 （Ｄ× ％） 端数切り捨て | Y40: 円
G41: □資格・認定（ → ）
K42: 事業者番号（受領委任)
B43: 決 裁 | D43: 課 長 | E43: 係 長 | G43: 係 員 | I43: 受 付 | K43: 支給 | O43: 起 案 | R43: 令和 年 月 日
O44: 決 裁 | R44: 令和 年 月 日
K45: 不支給 | O45: 決定通知 | R45: 令和 年 月 日
O46: 支 給 | R46: 令和 年 月 日

Sheet 同意書
A3: 同 意 書
C6: （あて先）
C7: 福岡市 区長
AO8: 令和 年 月 日
K11: 申請者住所 | S11: =基本情報!B5 -> 0
K14: 申請者氏名
K17: 被保険者番号
Z18: =基本情報!B7 -> 0
AJ20: ※署名（自筆）の場合は押印不要
D23: 私は、介護保険住宅改修に係る申請書の提出代行を、下記のものに依頼しましたので、申請に必要な範囲で、下記の者に私の介護保険の資格に関する事項、当該給付の状況、給付制限に関する事項について確認させることに同意します。
K30: 代理人住所 福岡市西区小戸１－１６－２４
K33: 代理人氏名 （株）介福本舗
K36: 申請者との関係 住宅改修事業者
D41: 点線以下、記載不要
D45: 【代理人本人確認】
D47: 確 認 資 料 | L47: 介護支援専門員証 ・ 運転免許証 ・ その他（ ）
AT50: 確認年月日

Sheet 承諾書
A1: 住宅改修にかかる承諾書
A4: （あて先）
A5: 福岡市 区長
AL7: 令和 年 月 日
T9: （住宅の所有者）
U11: 住 所
U14: 氏 名
U17: 連絡先 | Z17: （ | AE17: ） | AK17: -
F24: 私は、私が所有し | P24: =基本情報!B3 -> 0 | AC24: が入居する
F27: =基本情報!B5 -> 0 | AK27: の住宅について
F30: 入居者の身体上の理由により、介護保険の住宅改修をしたい旨の相談を受け、
F33: 改修内容を了承の上、これを承諾いたしましたのでお知らせいたします。

Sheet 理由書1
A1: 住宅改修が必要な理由書
A2: ＜基本情報＞
A3: 利用者 | B3: 被保険者番号 | C3: =基本情報!B7 -> 0 | L3: 明治 | R3: 作成者 | S3: 現地確認日 | U3: 45437 | Z3: 作成日 | AD3: 45437
H4: 年齢 | J4: 歳 | K4: 生年月日 | L4: 大正 | N4: 年 | O4: 月 | P4: 日
L5: 昭和
B6: 被保険者氏名 | C6: =基本情報!B3 -> 0 | H6: 要介護認定 | K6: 要支援 | M6: 要介護 | S6: 所属事業所 | U6: 株式会社 介福本舗
H7: （該当に○） | K7: １・２ | M7: １・２・３・４・５ | S7: 資格 | T7: （作成者が介護支援専門員でないとき） | U7: 住環境コーディネーター2級
B9: 住所 | C9: =基本情報!B5 -> 0 | S9: 氏名
S11: 連絡先 | U11: 092-985-0904
A13: 保険者 | B13: 確認日 | D13: 年 | E13: 月 | F13: 日 | G13: 評価欄
B15: 氏名
A18: ＜総合的状況＞
A19: 利用者の身体状況 | AC19: 福祉用具の利用状況と
AB20: 住宅改修後の想定 | AG20: 改 | AH20: 修 | AI20: 前 | AJ20: 改 | AK20: 修 | AL20: 後
Z21: ● | AA21: 車いす | AH21: □ | AK21: □
Z22: ● | AA22: 特殊寝台 | AH22: □ | AK22: □
Z23: ● | AA23: 床ずれ防止用具 | AH23: □ | AK23: □
Z24: ● | AA24: 体位変換器 | AH24: □ | AK24: □
A25: 介護状況 | Z25: ● | AA25: 手すり | AH25: □ | AK25: □
Z26: ● | AA26: スロープ | AH26: □ | AK26: □
Z27: ● | AA27: 歩行器 | AH27: □ | AK27: □
Z28: ● | AA28: 歩行補助つえ | AH28: □ | AK28: □
Z29: ● | AA29: 認知症老人徘徊感知機器 | AH29: □ | AK29: □
A30: 住宅改修により、利用者等は日常生活をどう変えたいか | Z30: ● | AA30: 移動用リフト | AH30: □ | AK30: □
Z31: ● | AA31: 腰掛便座 | AH31: □ | AK31: □
Z32: ● | AA32: 特殊尿器 | AH32: □ | AK32: □
Z33: ● | AA33: 入浴補助用具 | AH33: □ | AK33: □
Z34: ● | AA34: 簡易浴槽 | AH34: □ | AK34: □
Z35: ● | AA35: その他
Z38: ・ | AH38: □ | AK38: □
Z40: ・ | AH40: □ | AK40: □
Z42: ・ | AH42: □ | AK42: □

Sheet 理由書2
B1: 住宅改修が必要な理由書
B2: ＜Ｐ1の「総合的状況」を踏まえて、①改善をしようとしている生活動作②具体的な困難な状況③改修目的と改修の方針④改修項目を具体的に記入してください。＞
A3: 活動 | C3: ①改善をしようとしている生活動作 | F3: ② ①の具体的な困難な状況（・・・なので ・・・で困っている）を記入してください | I3: ③ 改修目的・期待効果をチェックした上で、改修の方針（・・・することで ・・・が改善できる）を記入してください | N3: ④ 改修項目（改修箇所） | Q3: 【② ①の具体的な困難な状況（・・・なので ・・・で困っている）を記入してください】 | R3: 【③ 改修目的・期待効果をチェックした上で、改修の方針（・・・することで ・・・が改善できる）を記入してください】
A5: 排泄 | B5: □ | C5: トイレまでの移動 | H5: □ | I5: できなかったことをできる | M5: □ | N5: 手すりの取付け | Q5: 下肢筋力が低下しトイレ内での安定した立ち座りができなくなっている。 | R5: トイレ内に手すりを付けることにより安定した立ち座りをできるようにする。
B6: □ | C6: トイレ出入口の出入 | I6: ようにする | N6: ( ) | Q6: トイレ便器までの移動が不安定で転倒の危険性が高い。 | R6: トイレ内に手すりを付けることにより便器までの移動を安定して行える。
C7: （扉の開閉を含む） | H7: □ | I7: 転倒等の防止、安全の確保 | Q7: トイレの扉の開閉が不安定で転倒の危険性が高い。 | R7: トイレ扉の開閉方向を変えることで転倒の危険性を低くできる。
B8: □ | C8: 便器からの立ち座り（移乗を含む） | H8: □ | I8: 動作の容易性の確保 | N8: ( ) | Q8: トイレ入口の段差が高くつまずく危険性が高い。 | R8: トイレ入口に手すりを付け扉の開閉を安全に行えるようにする。
B9: □ | C9: 衣服の着脱 | H9: □ | I9: 利用者の精神的負担や | Q9: トイレ内での衣服の着脱時の姿勢保持ができず介助者に負担がかかる。 | R9: トイレ入口の段差を解消することで転倒の危険性を低くする。
B10: □ | C10: 排泄時の姿勢保持 | I10: 不安の軽減 | N10: ( ) | R10: トイレ内に手すりを取り付け衣服着脱時の介助者の負担を軽減させる。
B11: □ | C11: 後始末 | H11: □ | I11: 介護者の負担の軽減
B12: □ | C12: その他（ ） | H12: □ | I12: その他（ ） | N12: ( )
A13: 入浴 | B13: □ | C13: 浴室までの移動 | H13: □ | I13: できなかったことをできる | Q13: 加齢による体力・筋力の低下で浴槽への出入りが困難。 | R13: 浴室内に手すりを取り付けることにより安定して浴槽内へ出入りができるようにする
B14: □ | C14: 衣服の着脱 | I14: ようにする | N14: ( ) | Q14: 下肢筋力の低下があり、浴室の出入りで転倒の危険性が高い | R14: 浴室入口に手すりを取り付けることにより安定して出入りをできるようにする。
B15: □ | C15: 浴室出入口の出入 | H15: □ | I15: 転倒等の防止、安全の確保 | Q15: 体力の低下に伴い浴室扉の開閉で転倒の危険性が高い。 | R15: 浴室入口を折れ戸にすることで安定した開閉ができる。また浴室内で転倒した場合でも扉の開閉が容易にできる
C16: （扉の開閉を含む） | H16: □ | I16: 動作の容易性の確保 | M16: □ | N16: 段差の解消 | Q16: 浴室洗い場での姿勢保持がむずかしく、立ち座りにふらつき危険。 | R16: 浴室洗い場に津すりの設置を行うことで姿勢保持を行い、安定した立ち座りもできるようにする。
B17: □ | C17: 浴室内での移動（立ち座りを含む） | H17: □ | I17: 利用者の精神的負担や | N17: ( ) | Q17: 浴室洗い場の床がすべりやすく転倒の危険性が高い。 | R17: 洗い場の床材を滑りにくいものに変え転倒の危険性を少なくする
B18: □ | C18: 洗い場での姿勢保持 | I18: 不安の軽減
C19: （洗体・洗髪を含む） | H19: □ | I19: 介護者の負担の軽減 | N19: ( )
B20: □ | C20: 浴槽の出入（立ち座りを含む） | H20: □ | I20: その他（ ）
B21: □ | C21: 浴槽内での姿勢保持 | N21: ( )
B22: □ | C22: その他（ ）
A23: 外出 | B23: □ | C23: 出入口までの屋内移動 | H23: □ | I23: できなかったことをできる | M23: □ | N23: 引き戸等への扉の取替え | Q23: 勝手口に手すりがなく出入りに苦労している。 | R23: 勝手口に手すりを取り付けることにより安全に出入りができるようにする
B24: □ | C24: 上がりかまちの昇降 | I24: ようにする | N24: ( ) | Q24: 外玄関通路が舗装されておらず車いすの移動ができず危険。 | R24: 外玄関通路を舗装することで安全に車いすで移動ができるようにし外出時の負担を減らす。
B25: □ | C25: 車いす等、装具の着脱 | H25: □ | I25: 転倒等の防止、安全の確保 | Q25: 門扉階段の段差が高く安定して昇降することが困難。 | R25: 門扉階段に手すりを取り付け安定して段差の昇降をできるようにする
B26: □ | C26: 履物の着脱 | H26: □ | I26: 動作の容易性の確保 | N26: ( )
B27: □ | C27: 出入口の出入 | H27: □ | I27: 利用者の精神的負担や
C28: （扉の開閉を含む） | I28: 不安の軽減 | M28: □ | N28: 便器の取替え
B29: □ | C29: 出入口から敷地外までの | H29: □ | I29: 介護者の負担の軽減 | N29: ( )
C30: 屋外移動 | H30: □ | I30: その他（ ）
B31: □ | C31: その他（ ） | N31: ( )
A32: その他の活動 | B32: □ | C32: 庭先の移動 | H32: □ | I32: できなかったことをできる | Q32: 庭に洗濯物を干しているが手すりがなく移動時に転倒の危険が高い。 | R32: 庭に手すりを設置することで安全に移動ができるようになる。
B33: □ | C33: 階段の昇降 | I33: ようにする | M33: □ | N33: 滑り防止等のための床材の変更 | Q33: 2階に寝室があるが階段に手すりがなく転倒の危険性が高い。 | R33: 階段に手すりがあることで寝室への移動を安全に行える。
B34: □ | C34: 廊下の移動 | H34: □ | I34: 転倒等の防止、安全の確保 | N34: ( ) | Q34: 下肢の筋力が低下しておりトイレや浴室までの動線の移動が困難。 | R34: 廊下に手すりを付けることにより安全にトイレや浴室までの移動ができるようにする。
B35: □ | C35: 洗面室の移動 | H35: □ | I35: 動作の容易性の確保 | Q35: 洗面室の出入りの際に段差があり転倒の危険性が高い。 | R35: 洗面室に手すりを取り付けることにより安全に出入りをできるようにする。
B36: □ | C36: 屋外の敷地 | H36: □ | I36: 利用者の精神的負担や | N36: ( )
B37: □ | C37: 居室の移動 | I37: 不安の軽減
H38: □ | I38: 介護者の負担の軽減 | M38: □ | N38: その他
H39: □ | I39: その他（ ） | N39: ( )
N41: ( )
N43: ( )

Sheet Sheet1
